Workbook

Sheet output>

Sheet 集計
C2: メルマガ登録→審査フォーム回答率 | D2: 審査フォーム→個別相談予約率 | E2: メルマガ登録→個別相談予約率
B3: 全体 | C3: =D16/C16 -> 0.28642659 | D3: =E16/D16 -> 0.7098646 | E3: =E16/C16 -> 0.2033241
B4: 20258月 | C4: =D17/C17 -> 0.27619048 | D4: =E17/D17 -> 0.8045977 | E4: =E17/C17 -> 0.22222222
B5: 20259月 | C5: =D18/C18 -> 0.22509225 | D5: =E18/D18 -> 0.95081967 | E5: =E18/C18 -> 0.21402214
B6: 202510月 | C6: =D19/C19 -> 0.27986348 | D6: =E19/D19 -> 0.57317073 | E6: =E19/C19 -> 0.16040956
B7: 202511月 | C7: =D20/C20 -> 0.33986928 | D7: =E20/D20 -> 0.63461538 | E7: =E20/C20 -> 0.21568627
B8: 202512月 | C8: =D21/C21 -> 0.62195122 | D8: =E21/D21 -> 0.58823529 | E8: =E21/C21 -> 0.36585366
B9: 20261月 | C9: =D22/C22 -> 0.18072289 | D9: =E22/D22 -> 0.8 | E9: =E22/C22 -> 0.14457831
B10: 20258-9月 | C10: =D23/C23 -> 0.26254376 | D10: =E23/D23 -> 0.67555556 | E10: =E23/C23 -> 0.17736289
B11: 202510-11月 | C11: =D24/C24 -> 0.29228687 | D11: =E24/D24 -> 0.58796296 | E11: =E24/C24 -> 0.17185386
B12: 202512-20261月 | C12: =D25/C25 -> 0.43829787 | D12: =E25/D25 -> 0.61165049 | E12: =E25/C25 -> 0.26808511
C15: メルマガ登録数 | D15: 審査フォーム回答数 | E15: 個別相談予約数
B16: 全体 | C16: =COUNTA(_xlfn.ANCHORARRAY(全体!E3)) -> 1805 | D16: =COUNTA(_xlfn.ANCHORARRAY(全体!L3)) -> 517 | E16: =COUNTA(_xlfn.ANCHORARRAY(全体!S3)) -> 367
B17: 20258月 | C17: =COUNTA('20258月'!B3:B632) -> 630 | D17: =COUNTA('20258月'!E3:E176) -> 174 | E17: =COUNTA('20258月'!H3:H142) -> 140
B18: 20259月 | C18: =COUNTA('20259月'!B3:B273) -> 271 | D18: =COUNTA('20259月'!E3:E63) -> 61 | E18: =COUNTA('20259月'!H3:H60) -> 58
B19: 202510月 | C19: =COUNTA('202510月'!B3:B588) -> 586 | D19: =COUNTA('202510月'!E3:E166) -> 164 | E19: =COUNTA('202510月'!H3:H96) -> 94
B20: 202511月 | C20: =COUNTA('202511月'!B3:B155) -> 153 | D20: =COUNTA('202511月'!E3:E54) -> 52 | E20: =COUNTA('202511月'!H3:H35) -> 33
B21: 202512月 | C21: =COUNTA('202512月'!B3:B84) -> 82 | D21: =COUNTA('202512月'!E3:E53) -> 51 | E21: =COUNTA('202512月'!H3:H32) -> 30
B22: 20261月 | C22: =COUNTA('20261月'!B3:B85) -> 83 | D22: =COUNTA('20261月'!E3:E17) -> 15 | E22: =COUNTA('20261月'!H3:H14) -> 12
B23: 20259-10月 | C23: =C18+C19 -> 857 | D23: =D18+D19 -> 225 | E23: =E18+E19 -> 152
B24: 202510-11月 | C24: =C19+C20 -> 739 | D24: =D19+D20 -> 216 | E24: =E19+E20 -> 127
B25: 202511-12月 | C25: =C20+C21 -> 235 | D25: =D20+D21 -> 103 | E25: =E20+E21 -> 63
B26: 202512-20261月 | C26: =C21+C22 -> 165 | D26: =D21+D22 -> 66 | E26: =E21+E22 -> 42

Sheet >process

Sheet 全体
B2: メルマガ登録者 | C2: 登録日時 | E2: メルマガ登録者(重複なし) | F2: 登録日時 | I2: 審査フォーム回答者 | J2: 登録日時 | L2: 審査フォーム回答者(重複なし) | M2: 登録日時 | P2: 個別相談予約者 | Q2: 登録日時 | S2: 個別相談予約者(重複なし) | T2: 登録日時
B3: rn010240@gmail.com | C3: 45876.933 | E3: {=_xlfn.UNIQUE(B3:B2213)} -> rn010240@gmail.com | F3: =_xlfn.XLOOKUP(E3,B:B,C:C) -> 45876.933 | I3: ty11055yoshi@gmail.com | J3: 45884.795 | L3: {=_xlfn.UNIQUE(I3:I753)} -> ty11055yoshi@gmail.com | M3: =_xlfn.XLOOKUP(L3,I:I,J:J) -> 45884.795 | P3: private@jun-otsu.com | Q3: 45874.959 | S3: {=_xlfn.UNIQUE(P3:P391)} -> private@jun-otsu.com | T3: =_xlfn.XLOOKUP(S3,P:P,Q:Q) -> 45874.959
B4: jin.hitoshi@gmail.com | C4: 45877.814 | E4: jin.hitoshi@gmail.com | F4: =_xlfn.XLOOKUP(E4,B:B,C:C) -> 45877.814 | I4: take.mas1969@gmail.com | J4: 45884.795 | L4: take.mas1969@gmail.com | M4: =_xlfn.XLOOKUP(L4,I:I,J:J) -> 45884.795 | P4: w.rainey-0840@kuf.biglobe.ne.jp | Q4: 45885.816 | S4: w.rainey-0840@kuf.biglobe.ne.jp | T4: =_xlfn.XLOOKUP(S4,P:P,Q:Q) -> 45885.816
B5: akikoko0110@yahoo.co.jp | C5: 45877.814 | E5: akikoko0110@yahoo.co.jp | F5: =_xlfn.XLOOKUP(E5,B:B,C:C) -> 45877.814 | I5: fujiwara.katsuya@gmail.com | J5: 45884.796 | L5: fujiwara.katsuya@gmail.com | M5: =_xlfn.XLOOKUP(L5,I:I,J:J) -> 45884.796 | P5: take.mas1969@gmail.com | Q5: 45885.816 | S5: take.mas1969@gmail.com | T5: =_xlfn.XLOOKUP(S5,P:P,Q:Q) -> 45885.816
B6: y.itagaki0528@gmail.com | C6: 45877.814 | E6: y.itagaki0528@gmail.com | F6: =_xlfn.XLOOKUP(E6,B:B,C:C) -> 45877.814 | I6: mymtystk@gmail.com | J6: 45884.796 | L6: mymtystk@gmail.com | M6: =_xlfn.XLOOKUP(L6,I:I,J:J) -> 45884.796 | P6: 99jastnet@gmail.com | Q6: 45885.816 | S6: 99jastnet@gmail.com | T6: =_xlfn.XLOOKUP(S6,P:P,Q:Q) -> 45885.816
B7: bellevie3253@gmail.com | C7: 45877.814 | E7: bellevie3253@gmail.com | F7: =_xlfn.XLOOKUP(E7,B:B,C:C) -> 45877.814 | I7: nao394d@gmail.com | J7: 45884.796 | L7: nao394d@gmail.com | M7: =_xlfn.XLOOKUP(L7,I:I,J:J) -> 45884.796 | P7: daisuke0776@gmail.com | Q7: 45885.816 | S7: daisuke0776@gmail.com | T7: =_xlfn.XLOOKUP(S7,P:P,Q:Q) -> 45885.816
B8: hiroshi.fujinawa@gmail.com | C8: 45877.814 | E8: hiroshi.fujinawa@gmail.com | F8: =_xlfn.XLOOKUP(E8,B:B,C:C) -> 45877.814 | I8: shizumemakiko@gmail.com | J8: 45884.798 | L8: shizumemakiko@gmail.com | M8: =_xlfn.XLOOKUP(L8,I:I,J:J) -> 45884.798 | P8: mymtystk@gmail.com | Q8: 45885.817 | S8: mymtystk@gmail.com | T8: =_xlfn.XLOOKUP(S8,P:P,Q:Q) -> 45885.817
B9: hiroya_95@yahoo.co.jp | C9: 45877.814 | E9: hiroya_95@yahoo.co.jp | F9: =_xlfn.XLOOKUP(E9,B:B,C:C) -> 45877.814 | I9: mmizuma@gmail.com | J9: 45884.8 | L9: mmizuma@gmail.com | M9: =_xlfn.XLOOKUP(L9,I:I,J:J) -> 45884.8 | P9: smile.jack317@docomo.ne.jp | Q9: 45885.819 | S9: smile.jack317@docomo.ne.jp | T9: =_xlfn.XLOOKUP(S9,P:P,Q:Q) -> 45885.819
B10: shoko2221@gmail.com | C10: 45877.814 | E10: shoko2221@gmail.com | F10: =_xlfn.XLOOKUP(E10,B:B,C:C) -> 45877.814 | I10: millenniumstar8@gmail.com | J10: 45884.802 | L10: millenniumstar8@gmail.com | M10: =_xlfn.XLOOKUP(L10,I:I,J:J) -> 45884.802 | P10: yamasaki.4s@icloud.com | Q10: 45885.821 | S10: yamasaki.4s@icloud.com | T10: =_xlfn.XLOOKUP(S10,P:P,Q:Q) -> 45885.821
B11: toshiki.1120.sawahata@gmail.com | C11: 45877.814 | E11: toshiki.1120.sawahata@gmail.com | F11: =_xlfn.XLOOKUP(E11,B:B,C:C) -> 45877.814 | I11: yamayu0462@gmail.com | J11: 45884.802 | L11: yamayu0462@gmail.com | M11: =_xlfn.XLOOKUP(L11,I:I,J:J) -> 45884.802 | P11: adachi.yoshinaga.4241@gmail.com | Q11: 45885.824 | S11: adachi.yoshinaga.4241@gmail.com | T11: =_xlfn.XLOOKUP(S11,P:P,Q:Q) -> 45885.824
B12: kenyoshioka888@gmail.com | C12: 45877.814 | E12: kenyoshioka888@gmail.com | F12: =_xlfn.XLOOKUP(E12,B:B,C:C) -> 45877.814 | I12: smile.jack317@docomo.ne.jp | J12: 45884.803 | L12: smile.jack317@docomo.ne.jp | M12: =_xlfn.XLOOKUP(L12,I:I,J:J) -> 45884.803 | P12: millenniumstar8@gmail.com | Q12: 45885.825 | S12: millenniumstar8@gmail.com | T12: =_xlfn.XLOOKUP(S12,P:P,Q:Q) -> 45885.825
B13: mmizuma@gmail.com | C13: 45877.814 | E13: mmizuma@gmail.com | F13: =_xlfn.XLOOKUP(E13,B:B,C:C) -> 45877.814 | I13: s.takeda000@icloud.com | J13: 45884.805 | L13: s.takeda000@icloud.com | M13: =_xlfn.XLOOKUP(L13,I:I,J:J) -> 45884.805 | P13: kmd249yamaji@gmail.com | Q13: 45885.826 | S13: kmd249yamaji@gmail.com | T13: =_xlfn.XLOOKUP(S13,P:P,Q:Q) -> 45885.826
B14: okudera.mit@gmail.com | C14: 45877.815 | E14: okudera.mit@gmail.com | F14: =_xlfn.XLOOKUP(E14,B:B,C:C) -> 45877.815 | I14: ganbamonta@gmail.com | J14: 45884.805 | L14: ganbamonta@gmail.com | M14: =_xlfn.XLOOKUP(L14,I:I,J:J) -> 45884.805 | P14: 39@aramaa.net | Q14: 45885.826 | S14: 39@aramaa.net | T14: =_xlfn.XLOOKUP(S14,P:P,Q:Q) -> 45885.826
B15: y6649851@gmail.com | C15: 45877.815 | E15: y6649851@gmail.com | F15: =_xlfn.XLOOKUP(E15,B:B,C:C) -> 45877.815 | I15: heckel371@yahoo.co.jp | J15: 45884.807 | L15: heckel371@yahoo.co.jp | M15: =_xlfn.XLOOKUP(L15,I:I,J:J) -> 45884.807 | P15: tkiku62@gmail.com | Q15: 45885.827 | S15: tkiku62@gmail.com | T15: =_xlfn.XLOOKUP(S15,P:P,Q:Q) -> 45885.827
... B369: miuratomoya@ymail.ne.jp | C369: 45881.41 | E369: 467tombi@gmail.com | F369: =_xlfn.XLOOKUP(E369,B:B,C:C) -> 45881.429 | I369: welcome4524@yahoo.co.jp | J369: 45945.643 | L369: yjomr.0619@gmail.com | M369: =_xlfn.XLOOKUP(L369,I:I,J:J) -> 45950.87 | P369: masakiyokyoumisa@ozzio.jp | Q369: 46013.122 | S369: takec3.1824@gmail.com | T369: =_xlfn.XLOOKUP(S369,P:P,Q:Q) -> 46038.849
B370: 467tombi@gmail.com | C370: 45881.429 | E370: masamikrt82@gmail.com | F370: =_xlfn.XLOOKUP(E370,B:B,C:C) -> 45881.44 | I370: a.mizoguchi.hyg@gmail.com | J370: 45945.739 | L370: u3w1qz2ni12bbyb2f2mb@rakumail.jp | M370: =_xlfn.XLOOKUP(L370,I:I,J:J) -> 45950.966 | P370: sanssjp006@gmail.com | Q370: 46013.923
B371: masamikrt82@gmail.com | C371: 45881.44 | E371: Akiko1k@hotmail.com | F371: =_xlfn.XLOOKUP(E371,B:B,C:C) -> 45881.463 | I371: zippopo510@gmail.com | J371: 45945.771 | L371: osushi.karma@gmail.com | M371: =_xlfn.XLOOKUP(L371,I:I,J:J) -> 45951.133 | P371: kinoshita.oka@gmail.com | Q371: 46013.95
B372: Akiko1k@hotmail.com | C372: 45881.463 | E372: hiromi0701suzu@gmail.com | F372: =_xlfn.XLOOKUP(E372,B:B,C:C) -> 45881.472 | I372: fujisanfujisanfujisan@gmail.com | J372: 45945.836 | L372: jamaica-reggae-kanchan-0701@docomo.ne.jp | M372: =_xlfn.XLOOKUP(L372,I:I,J:J) -> 45951.378 | P372: sena.k1017@icloud.com | Q372: 46014.653
B373: hiromi0701suzu@gmail.com | C373: 45881.472 | E373: yuki.kawamura0707@gmail.com | F373: =_xlfn.XLOOKUP(E373,B:B,C:C) -> 45881.477 | I373: nariaki.tada@icloud.com | J373: 45945.866 | L373: nobuaki24@yahoo.ne.jp | M373: =_xlfn.XLOOKUP(L373,I:I,J:J) -> 45951.634 | P373: ohtsuka@spre-ad.co.jp | Q373: 46015.587
B374: yuki.kawamura0707@gmail.com | C374: 45881.477 | E374: mase.mase.masse@gmail.com | F374: =_xlfn.XLOOKUP(E374,B:B,C:C) -> 45881.484 | I374: changeon9@gmail.com | J374: 45945.952 | L374: shinya_okada66@yahoo.co.jp | M374: =_xlfn.XLOOKUP(L374,I:I,J:J) -> 45951.927 | P374: avs0522@gmail.com | Q374: 46015.943
B375: mase.mase.masse@gmail.com | C375: 45881.484 | E375: soukon555@gmail.com | F375: =_xlfn.XLOOKUP(E375,B:B,C:C) -> 45881.514 | I375: kuge2311@yahoo.co.jp | J375: 45945.995 | L375: karintou3224@gmail.com | M375: =_xlfn.XLOOKUP(L375,I:I,J:J) -> 45951.957 | P375: w2022128124w@icloud.com | Q375: 46016.335
B376: soukon555@gmail.com | C376: 45881.514 | E376: asao3313@gmail.com | F376: =_xlfn.XLOOKUP(E376,B:B,C:C) -> 45881.588 | I376: dsswingart@gmail.com | J376: 45946.069 | L376: goindia2025@hotmail.com | M376: =_xlfn.XLOOKUP(L376,I:I,J:J) -> 45952.683 | P376: akira.4537@gmail.com | Q376: 46019.525
B377: asao3313@gmail.com | C377: 45881.588 | E377: kibune27@yahoo.co.jp | F377: =_xlfn.XLOOKUP(E377,B:B,C:C) -> 45881.688 | I377: active2526@yahoo.co.jp | J377: 45946.36 | L377: gimii0620@gmail.com | M377: =_xlfn.XLOOKUP(L377,I:I,J:J) -> 45953.859 | P377: laneige1221@gmail.com | Q377: 46020.23
B378: kibune27@yahoo.co.jp | C378: 45881.688 | E378: skyworudwairudo@gmail.com | F378: =_xlfn.XLOOKUP(E378,B:B,C:C) -> 45881.703 | I378: airiharuhi@hotmail.com | J378: 45946.404 | L378: nyanta.jyajya@gmail.com | M378: =_xlfn.XLOOKUP(L378,I:I,J:J) -> 45953.929 | P378: karua1229@yahoo.co.jp | Q378: 46023.986
B379: skyworudwairudo@gmail.com | C379: 45881.703 | E379: shiratori358@gmail.com | F379: =_xlfn.XLOOKUP(E379,B:B,C:C) -> 45881.713 | I379: monkiti369@gmail.com | J379: 45946.515 | L379: kuro7096@okinawa.li | M379: =_xlfn.XLOOKUP(L379,I:I,J:J) -> 45953.967 | P379: youko405xx@gmail.com | Q379: 46025.958
B380: shiratori358@gmail.com | C380: 45881.713 | E380: wakatosa@yahoo.co.jp | F380: =_xlfn.XLOOKUP(E380,B:B,C:C) -> 45881.769 | I380: shinosjapan@yahoo.co.jp | J380: 45946.632 | L380: crptufnf@gmail.com | M380: =_xlfn.XLOOKUP(L380,I:I,J:J) -> 45953.999 | P380: goodfeeling.goodtiming@gmail.com | Q380: 46026.921
B381: wakatosa@yahoo.co.jp | C381: 45881.769 | E381: toto.oku19@outlook.jp | F381: =_xlfn.XLOOKUP(E381,B:B,C:C) -> 45881.798 | I381: masaki29601119@icloud.com | J381: 45946.829 | L381: wbr81kei@gmail.com | M381: =_xlfn.XLOOKUP(L381,I:I,J:J) -> 45954.329 | P381: a.mizoguchi.hyg@gmail.com | Q381: 46027.377
... B391: steelkan900517@gmail.com | C391: 45882.327 | E391: seminar@sevencolorsdream.com | F391: =_xlfn.XLOOKUP(E391,B:B,C:C) -> 45882.331 | I391: dsswingart@gmail.com | J391: 45947.927 | L391: s52ck93bb14t@kpa.biglobe.ne.jp | M391: =_xlfn.XLOOKUP(L391,I:I,J:J) -> 45957.571 | P391: takec3.1824@gmail.com | Q391: 46038.849
B392: seminar@sevencolorsdream.com | C392: 45882.331 | E392: toshiya3.soso@gmail.com | F392: =_xlfn.XLOOKUP(E392,B:B,C:C) -> 45882.831 | I392: Yumikomuramatsu1957@gmail.com | J392: 45948.824 | L392: risa1031@hotmail.com | M392: =_xlfn.XLOOKUP(L392,I:I,J:J) -> 45957.751
B393: toshiya3.soso@gmail.com | C393: 45882.831 | E393: kawasenoimaaki@yahoo.co.jp | F393: =_xlfn.XLOOKUP(E393,B:B,C:C) -> 45882.915 | I393: asp5247@yahoo.co.jp | J393: 45948.885 | L393: et.0408@docomo.ne.jp | M393: =_xlfn.XLOOKUP(L393,I:I,J:J) -> 45959.933
B394: kawasenoimaaki@yahoo.co.jp | C394: 45882.915 | E394: yk.ogawa0313@gmail.com | F394: =_xlfn.XLOOKUP(E394,B:B,C:C) -> 45883.199 | I394: r0y9o1w9sk@gmail.com | J394: 45948.891 | L394: l.grazie.naga@gmail.com | M394: =_xlfn.XLOOKUP(L394,I:I,J:J) -> 45960.03
B395: yk.ogawa0313@gmail.com | C395: 45883.199 | E395: wbr81kei@gmail.com | F395: =_xlfn.XLOOKUP(E395,B:B,C:C) -> 45883.635 | I395: dsswingart@gmail.com | J395: 45948.905 | L395: colorscheme.1215@gmail.com | M395: =_xlfn.XLOOKUP(L395,I:I,J:J) -> 45960.062
B396: wbr81kei@gmail.com | C396: 45883.635 | E396: n_88_grow@yahoo.co.jp | F396: =_xlfn.XLOOKUP(E396,B:B,C:C) -> 45883.803 | I396: miekodaisuki@gmail.com | J396: 45948.92 | L396: wpjp358@gmail.com | M396: =_xlfn.XLOOKUP(L396,I:I,J:J) -> 45960.178
B397: n_88_grow@yahoo.co.jp | C397: 45883.803 | E397: tymahalo8@gmail.com | F397: =_xlfn.XLOOKUP(E397,B:B,C:C) -> 45883.805 | I397: syamunekokubo@gmail.com | J397: 45948.986 | L397: seaman1192kiki@yahoo.co.jp | M397: =_xlfn.XLOOKUP(L397,I:I,J:J) -> 45960.499
B398: tymahalo8@gmail.com | C398: 45883.805 | E398: ken964fu@ezweb.ne.jp | F398: =_xlfn.XLOOKUP(E398,B:B,C:C) -> 45884.793 | I398: izumikawa0925@gmail.com | J398: 45949.029 | L398: swimming5150@gmail.com | M398: =_xlfn.XLOOKUP(L398,I:I,J:J) -> 45960.607
B399: ken964fu@ezweb.ne.jp | C399: 45884.793 | E399: minalf102263@gmail.com | F399: =_xlfn.XLOOKUP(E399,B:B,C:C) -> 45884.805 | I399: marrokuu11@gmail.com | J399: 45949.105 | L399: kkkeita_dayo@yahoo.co.jp | M399: =_xlfn.XLOOKUP(L399,I:I,J:J) -> 45960.872
B400: minalf102263@gmail.com | C400: 45884.805 | E400: yoshitakaoshima@gmail.com | F400: =_xlfn.XLOOKUP(E400,B:B,C:C) -> 45885.561 | I400: yukakunichika@yahoo.co.jp | J400: 45949.442 | L400: pcat6270@gmai,com | M400: =_xlfn.XLOOKUP(L400,I:I,J:J) -> 45961.477
B401: yoshitakaoshima@gmail.com | C401: 45885.561 | E401: takahiro.9.8.yamato@gmail.com | F401: =_xlfn.XLOOKUP(E401,B:B,C:C) -> 45885.848 | I401: fujihama.194@gmail.com | J401: 45949.444 | L401: kan.sentimental53@i.softbank.jp | M401: =_xlfn.XLOOKUP(L401,I:I,J:J) -> 45962.737
B402: takahiro.9.8.yamato@gmail.com | C402: 45885.848 | E402: gfm100taka@gmail.com | F402: =_xlfn.XLOOKUP(E402,B:B,C:C) -> 45885.854 | I402: asukachan0718@yahoo.co.jp | J402: 45949.562 | L402: cocoe0505@gmail.com | M402: =_xlfn.XLOOKUP(L402,I:I,J:J) -> 45963.753
B403: gfm100taka@gmail.com | C403: 45885.854 | E403: hatanotoshi@yahoo.co.jp | F403: =_xlfn.XLOOKUP(E403,B:B,C:C) -> 45885.92 | I403: okiraku8848@yahoo.co.jp | J403: 45949.657 | L403: yamada@ikkoo.info | M403: =_xlfn.XLOOKUP(L403,I:I,J:J) -> 45964.863
...

Sheet 20258月
B2: メルマガ登録者(重複なし) | C2: 登録日時 | E2: 審査フォーム回答者(重複なし) | F2: 登録日時 | H2: 個別相談予約者(重複なし) | I2: 登録日時
B3: rn010240@gmail.com | C3: 45876.933 | E3: ty11055yoshi@gmail.com | F3: 45884.795 | H3: private@jun-otsu.com | I3: 45874.959
B4: jin.hitoshi@gmail.com | C4: 45877.814 | E4: take.mas1969@gmail.com | F4: 45884.795 | H4: w.rainey-0840@kuf.biglobe.ne.jp | I4: 45885.816
B5: akikoko0110@yahoo.co.jp | C5: 45877.814 | E5: fujiwara.katsuya@gmail.com | F5: 45884.796 | H5: take.mas1969@gmail.com | I5: 45885.816
B6: y.itagaki0528@gmail.com | C6: 45877.814 | E6: mymtystk@gmail.com | F6: 45884.796 | H6: 99jastnet@gmail.com | I6: 45885.816
B7: bellevie3253@gmail.com | C7: 45877.814 | E7: nao394d@gmail.com | F7: 45884.796 | H7: daisuke0776@gmail.com | I7: 45885.816
B8: hiroshi.fujinawa@gmail.com | C8: 45877.814 | E8: shizumemakiko@gmail.com | F8: 45884.798 | H8: mymtystk@gmail.com | I8: 45885.817
B9: hiroya_95@yahoo.co.jp | C9: 45877.814 | E9: mmizuma@gmail.com | F9: 45884.8 | H9: smile.jack317@docomo.ne.jp | I9: 45885.819
B10: shoko2221@gmail.com | C10: 45877.814 | E10: millenniumstar8@gmail.com | F10: 45884.802 | H10: yamasaki.4s@icloud.com | I10: 45885.821
B11: toshiki.1120.sawahata@gmail.com | C11: 45877.814 | E11: yamayu0462@gmail.com | F11: 45884.802 | H11: adachi.yoshinaga.4241@gmail.com | I11: 45885.824
B12: kenyoshioka888@gmail.com | C12: 45877.814 | E12: smile.jack317@docomo.ne.jp | F12: 45884.803 | H12: millenniumstar8@gmail.com | I12: 45885.825
B13: mmizuma@gmail.com | C13: 45877.814 | E13: s.takeda000@icloud.com | F13: 45884.805 | H13: kmd249yamaji@gmail.com | I13: 45885.826
B14: okudera.mit@gmail.com | C14: 45877.815 | E14: ganbamonta@gmail.com | F14: 45884.805 | H14: 39@aramaa.net | I14: 45885.826
... B142: yakisobapan0083@gmail.com | C142: 45878.299 | E142: kawanokaiji0412@yahoo.co.jp | F142: 45890.797 | H142: yuuzouka@yahoo.co.jp | I142: 45899.976
B143: shigetaka0427@gmail.com | C143: 45878.301 | E143: uusamat2018@gmail.com | F143: 45890.872
B144: dreamopen0001@gmail.com | C144: 45878.308 | E144: k.masashi.5520@gmail.com | F144: 45891.02
B145: ssfrst77@gmail.com | C145: 45878.313 | E145: cosmic4c@gmail.com | F145: 45891.429
B146: 0609maikumaiku@gmail.com | C146: 45878.317 | E146: kaminade@gmail.com | F146: 45891.599
B147: paribmw369@gmail.com | C147: 45878.322 | E147: yuuzouka@yahoo.co.jp | F147: 45891.662
B148: asatokj1202@gmail.com | C148: 45878.326 | E148: aoanela.aloha@gmail.com | F148: 45891.747
B149: yamayu0462@gmail.com | C149: 45878.348 | E149: kyonbokun0509@gmail.com | F149: 45893.017
B150: hagi425872@gmail.com | C150: 45878.349 | E150: koujimukasa@gmail.com | F150: 45893.923
B151: keigokawano5@gmail.com | C151: 45878.357 | E151: taichirokubo1@gmail.com | F151: 45893.927
B152: 99jastnet@gmail.com | C152: 45878.364 | E152: hdakzk@gmail.com | F152: 45894.008
B153: sato.mercari@gmail.com | C153: 45878.38 | E153: kolwiin55@gmail.com | F153: 45894.12
B154: 39@aramaa.net | C154: 45878.394 | E154: bhxjp197@gmail.com | F154: 45894.736
... B176: everyhappy358@gmail.com | C176: 45878.821 | E176: rn010240@gmail.com | F176: 45887.863
B177: ykowaki430@gmail.com | C177: 45878.826
B178: lagoon3629@gmail.com | C178: 45878.829
B179: 1907suganuma@gmail.com | C179: 45878.836
B180: ss250zukka@gmail.com | C180: 45878.836
B181: ms.9941@icloud.com | C181: 45878.836
B182: toyaman23-2525@docomo.ne.jp | C182: 45878.837
B183: klein_arc@yahoo.co.jp | C183: 45878.837
B184: yagutaka0927@gmail.com | C184: 45878.837
B185: tiko40tyan@gmail.com | C185: 45878.838
B186: valx347@gmail.com | C186: 45878.838
B187: ktkhs106@gmail.com | C187: 45878.838
B188: kou0494@gmail.com | C188: 45878.839
... B632: hjctf875@yahoo.co.jp | C632: 45900.942

Sheet 20259月
B2: メルマガ登録者(重複なし) | C2: 登録日時 | E2: 審査フォーム回答者(重複なし) | F2: 登録日時 | H2: 個別相談予約者(重複なし) | I2: 登録日時
B3: saeko-nishi168@nifty.com | C3: 45901.148 | E3: saeko-nishi168@nifty.com | F3: 45901.152 | H3: saeko-nishi168@nifty.com | I3: 45902.82
B4: trendfollower2013@gmail.com | C4: 45901.331 | E4: sakuboo85@gmail.com | F4: 45901.276 | H4: okada@nkeg.net | I4: 45901.603
B5: babibubeboddha@gmail.com | C5: 45901.339 | E5: emi.emi.honey@gmail.com | F5: 45901.925 | H5: harumir7@gmail.com | I5: 45901.797
B6: naopn.shiga.6619@gmail.com | C6: 45901.348 | E6: hi_standard_a_i_m_h_stay_gold@yahoo.co.jp | F6: 45902.061 | H6: hypocrite5843@gmail.com | I6: 45901.816
B7: arina.wada1@gmail.com | C7: 45901.401 | E7: hayato39ok@gmail.com | F7: 45902.768 | H7: kefu051204@outlook.jp | I7: 45902.596
B8: info@fishingclub.info | C8: 45901.475 | E8: yoshiro19801225@gmail.com | F8: 45903.985 | H8: emi.emi.honey@gmail.com | I8: 45902.883
B9: gypsy.666t@gmail.com | C9: 45901.492 | E9: armando.tomigusuku@gmail.com | F9: 45904.314 | H9: ken964fu@ezweb.ne.jp | I9: 45903.875
B10: katokatsu333@gmail.com | C10: 45901.523 | E10: hatamori_h@yahoo.co.jp | F10: 45904.82 | H10: miguel.akira.ota@gmail.com | I10: 45904.316
B11: kamikaze@sun.gmobb.jp | C11: 45901.596 | E11: nasutomato93@gmail.com | F11: 45904.927 | H11: yoshiro19801225@gmail.com | I11: 45904.888
B12: mtrskb4010@yahoo.co.jp | C12: 45901.745 | E12: mmyo.ja.akiko@gmail.com | F12: 45904.928 | H12: takuya.tsukada@icloud.com | I12: 45904.901
B13: kikit39@icloud.com | C13: 45901.856 | E13: hitomimakeup0130@icloud.com | F13: 45906.53 | H13: sakuboo85@gmail.con | I13: 45904.906
B14: tanioku.kazuo.4.8@gmail.com | C14: 45901.896 | E14: tomiguma@gmail.com | F14: 45906.807 | H14: hitomimakeup0130@icloud.com | I14: 45906.617
... B60: tutankhamen7656@gmail.com | C60: 45907.418 | E60: chaco.0114.sato@gmail.com | F60: 45929.73 | H60: kibishimodaira7306@gmail.com | I60: 45930.75
B61: koufuk0322@gmail.com | C61: 45907.445 | E61: kibishimodaira7306@gmail.com | F61: 45929.983
B62: konmaniwa725@gmail.com | C62: 45907.591 | E62: c.s7mybnesy61@gmail.com | F62: 45930.165
B63: kazoo529@gmail.com | C63: 45907.658 | E63: oreore.orz48@gmail.com | F63: 45930.932
B64: g4u373@gmail.com | C64: 45907.789
B65: yu.21_bad.endoftime@icloud.com | C65: 45907.843
B66: harley88088@yahoo.co.jp | C66: 45907.931
B67: takakoba30162@gmail.com | C67: 45907.936
B68: etakako21@yahoo.co.jp | C68: 45907.961
B69: skyhigh_tanney@yahoo.co.jp | C69: 45907.962
B70: genelsbass@gmail.com | C70: 45908.301
B71: arigatougozaimasu3byakumanben@gmail.com | C71: 45908.418
B72: tu19661121@gmail.com | C72: 45908.448
B73: kikurinn@yahoo.co.jp | C73: 45908.458
B74: legare.ueda@gmail.com | C74: 45908.58
B75: copymikako@gmail.com | C75: 45908.839
... B273: fromyuu2525@gmail.com | C273: 45930.963

Sheet 202510月
B2: メルマガ登録者(重複なし) | C2: 登録日時 | E2: 審査フォーム回答者(重複なし) | F2: 登録日時 | H2: 個別相談予約者(重複なし) | I2: 登録日時
B3: murakamijapon@gmail.com | C3: 45931.016 | E3: d.1986.com@gmail.com | F3: 45931.095 | H3: d.1986.com@gmail.com | I3: 45931.383
B4: aloha808hi@gmail.com | C4: 45931.045 | E4: kawatatsu52gg@gmail.com | F4: 45931.316 | H4: kawatatsu52gg@gmail.com | I4: 45931.473
B5: d.1986.com@gmail.com | C5: 45931.094 | E5: mitsunori1105ken@gmail.com | F5: 45931.407 | H5: mitz.ken.0826@yahoo.ne.jp | I5: 45931.506
B6: 1959hiroaki5963@gmail.com | C6: 45931.23 | E6: mitz.ken.0826@yahoo.ne.jp | F6: 45931.419 | H6: oreore.orz48@gmail.com | I6: 45931.575
B7: kawatatsu52gg@gmail.com | C7: 45931.309 | E7: rukou.ryukou@gmail.com | F7: 45931.691 | H7: rukou.ryukou@gmail.com | I7: 45931.803
B8: kubotada1122@gmail.com | C8: 45931.31 | E8: d9control@gmail.com | F8: 45931.778 | H8: morimori19720216@gmail.com | I8: 45932.91
B9: mitz.ken.0826@yahoo.ne.jp | C9: 45931.337 | E9: kawaihideharu55@gmail.com | F9: 45931.844 | H9: hukushima112028@gmail.com | I9: 45933.359
B10: kasadakai@gmail.com | C10: 45931.347 | E10: xoxo75tkd@yahoo.co.jp | F10: 45931.97 | H10: advance4world@gmail.com | I10: 45933.445
B11: hiroshi.sriracha@gmail.com | C11: 45931.373 | E11: morimori19720216@gmail.com | F11: 45932.28 | H11: ryutahirakawa@gmail.com | I11: 45933.447
B12: okachikaka@gmail.com | C12: 45931.389 | E12: 269fuku29niko25369@gmail.com | F12: 45932.546 | H12: supremus8880@gmail.com | I12: 45933.505
B13: tanemame@gmail.com | C13: 45931.39 | E13: smotokun0129@gmail.com | F13: 45932.551 | H13: marbow.mh@gmail.com | I13: 45933.772
B14: ndnz1045@gmail.com | C14: 45931.39 | E14: advance4world@gmail.com | F14: 45932.555 | H14: tomoya.773.235@gmail.com | I14: 45933.869
... B96: hiromax2022@gmail.com | C96: 45935.247 | E96: welcome4524@yahoo.co.jp | F96: 45945.643 | H96: seaman1192kiki@yahoo.co.jp | I96: 45961.848
B97: maeshima50@gmail.com | C97: 45935.298 | E97: a.mizoguchi.hyg@gmail.com | F97: 45945.739
B98: aamendokusei@gmail.com | C98: 45935.325 | E98: zippopo510@gmail.com | F98: 45945.771
B99: proton1130@gmail.com | C99: 45935.424 | E99: fujisanfujisanfujisan@gmail.com | F99: 45945.836
B100: hiromasa.m44@gmail.com | C100: 45935.443 | E100: nariaki.tada@icloud.com | F100: 45945.866
B101: samu3212@gmail.com | C101: 45935.445 | E101: changeon9@gmail.com | F101: 45945.952
B102: loveless8888@gmail.com | C102: 45935.522 | E102: kuge2311@yahoo.co.jp | F102: 45945.995
B103: inadom358@icloud.com | C103: 45935.546 | E103: dsswingart@gmail.com | F103: 45946.069
B104: mr.freelance011724@gmail.com | C104: 45935.548 | E104: active2526@yahoo.co.jp | F104: 45946.36
B105: yukiafrica@gmail.com | C105: 45935.581 | E105: airiharuhi@hotmail.com | F105: 45946.404
B106: yuka.pc.ado@gmail.com | C106: 45935.61 | E106: monkiti369@gmail.com | F106: 45946.515
B107: ricorico.060721@gmail.com | C107: 45935.642 | E107: shinosjapan@yahoo.co.jp | F107: 45946.632
B108: chi29510824@yahoo.co.jp | C108: 45935.795 | E108: masaki29601119@icloud.com | F108: 45946.829
... B166: pobbytodingan214@yahoo.co.jp | C166: 45939.163 | E166: pcat6270@gmai,com | F166: 45961.477
B167: got-11042012@i.softbank.jp | C167: 45939.214
B168: takahashi588@gmail.com | C168: 45939.243
B169: lovemiki43@gmail.com | C169: 45939.317
B170: jan5572001@yahoo.com.jp | C170: 45939.338
B171: mokohorii@yahoo.co.jp | C171: 45939.34
B172: osushi.karma@gmail.com | C172: 45939.343
B173: ashomi@icloud.com | C173: 45939.358
B174: ayumi.k538@gmail.com | C174: 45939.406
B175: sunsetkk3@gmail.com | C175: 45939.452
B176: mi.yakky.peace2525@gmail.com | C176: 45939.615
B177: macuro164@gmail.com | C177: 45939.627
B178: mihokomasato@gmail.com | C178: 45939.64
... B588: wellfly.pictures@gmail.com | C588: 45961.895

Sheet 202511月
B2: メルマガ登録者(重複なし) | C2: 登録日時 | E2: 審査フォーム回答者(重複なし) | F2: 登録日時 | H2: 個別相談予約者(重複なし) | I2: 登録日時
B3: dolphin-blue-2527@ezweb.ne.jp | C3: 45962.484 | E3: kan.sentimental53@i.softbank.jp | F3: 45962.737 | H3: dsswingart@gmail.com | I3: 45962.355
B4: kan.sentimental53@i.softbank.jp | C4: 45962.733 | E4: cocoe0505@gmail.com | F4: 45963.753 | H4: r0y9o1w9sk@gmail.com | I4: 45962.38
B5: yogetjp@yahoo.co.jp | C5: 45962.993 | E5: yamada@ikkoo.info | F5: 45964.863 | H5: wgjp358@gmail.com | I5: 45962.5
B6: Shigerukamata@gmail.com | C6: 45963.371 | E6: crash4405@gmail.com | F6: 45965.257 | H6: izumikawa0925@gmail.com | I6: 45963.71
B7: hideaki_takehisa@yahoo.co.jp | C7: 45963.676 | E7: seresuta8132@yahoo.co.jp | F7: 45966.002 | H7: cocoe0505@gmail.com | I7: 45963.853
B8: hirakawa59@gmail.com | C8: 45964.819 | E8: minoharry@gmail.com | F8: 45966.567 | H8: okumanchouja358@gmail.com | I8: 45963.921
B9: kmiyamoto537@gmail.com | C9: 45964.824 | E9: sayo.momo.saku@gmail.com | F9: 45966.661 | H9: rovestory0210@yahoo.co.jp | I9: 45965.958
B10: yamada@ikkoo.info | C10: 45964.828 | E10: sdcfx72@gmail.com | F10: 45966.926 | H10: sdcfx72@gmail.com | I10: 45967.115
B11: h_takino3@yahoo.co.jp | C11: 45964.87 | E11: anna.miyu@ezweb.ne.jp | F11: 45967.067 | H11: 4080000abc@gmail.com | I11: 45967.312
B12: rsato1113@gmail.com | C12: 45964.881 | E12: yajimaen8200@gmail.com | F12: 45967.862 | H12: minoharry@gmail.com | I12: 45967.39
B13: kalitakiya0205@gmail.com | C13: 45964.915 | E13: azaz02170217@yahoo.co.jp | F13: 45968.415 | H13: anna.miyu@ezweb.ne.jp | I13: 45967.515
B14: sszk4050@gmail.com | C14: 45964.92 | E14: hagi160160@gmail.com | F14: 45969.469 | H14: kotobukiclubjp@gmail.com | I14: 45969.494
... B35: tomomi_kujp@yahoo.co.jp | C35: 45968.306 | E35: firstman817@gmail.com | F35: 45979.51 | H35: kajigonn18@yahoo.co.jp | I35: 45991.344
B36: azaz02170217@yahoo.co.jp | C36: 45968.35 | E36: aa19890112@yahoo.co.jp | F36: 45979.68
B37: noaist7@gmail.com | C37: 45968.532 | E37: kajigonn18@yahoo.co.jp | F37: 45979.72
B38: hagi160160@gmail.com | C38: 45969.279 | E38: kinoshita.oka@gmail.com | F38: 45980.714
B39: muchi2p-chic_s-k@docomo.ne.jp | C39: 45969.426 | E39: ryo2good51@gmail.com | F39: 45981.377
B40: mstay.goldship47@gmail.com | C40: 45969.718 | E40: ykouzaki@ku.kumagaigumi.co.jp | F40: 45983.493
B41: contrail.intheblue@gmail.com | C41: 45969.759 | E41: umi2019.12.24@gmail.com | F41: 45983.8
B42: integral2006@yahoo.co.jp | C42: 45970.312 | E42: valx347@gmail.com | F42: 45983.841
B43: yoshida_9518@yahoo.co.jp | C43: 45970.492 | E43: yaya12250916@gmail.com | F43: 45984.137
B44: nao.igu-.1536@docomo.ne.jp | C44: 45970.846 | E44: aamms1480@gmail.com | F44: 45984.437
B45: ihouse8@icloud.com | C45: 45971.81 | E45: thomas_m.k.night@icloud.com | F45: 45984.909
B46: takasannet2005@gmail.com | C46: 45971.852 | E46: rising.life.0073@gmail.com | F46: 45984.915
B47: kamishi_jipang@yahoo.co.jp | C47: 45971.854 | E47: y_bottle_nose@hotmail.com | F47: 45985.845
... B54: gs3508899@gmail.com | C54: 45972.299 | E54: dc433345_216_2@icloud.com | F54: 45991.933
B55: manai8998@icloud.com | C55: 45972.357
B56: sekiyamatokou@icloud.com | C56: 45972.395
B57: kaz-_-428@i.softbank.jp | C57: 45972.395
B58: naoko19670516@gmail.com | C58: 45972.422
B59: mochan1118@gmail.com | C59: 45972.451
B60: sa.yama5522@gmail.com | C60: 45972.476
B61: ya.ma.san.go75@gmail.com | C61: 45972.656
B62: yyouko612@gmail.com | C62: 45972.735
B63: culin.1231@gmail.com | C63: 45972.765
B64: y_ichige@yahoo.co.jp | C64: 45972.781
B65: sana_ip13yj@yahoo.co.jp | C65: 45972.805
B66: takao.1017.0617@gmail.com | C66: 45972.808
... B155: cubay821@gmail.com | C155: 45991.935

Sheet 202512月
B2: メルマガ登録者(重複なし) | C2: 登録日時 | E2: 審査フォーム回答者(重複なし) | F2: 登録日時 | H2: 個別相談予約者(重複なし) | I2: 登録日時
B3: hikarinet2011@gmail.com | C3: 45992 | E3: discovery7247@gmail.com | F3: 45992.295 | H3: dc433345_216_2@icloud.com | I3: 45992.216
B4: nogan491@gmail.com | C4: 45992.085 | E4: ahaba.300@gmail.com | F4: 45993.854 | H4: winwinwin.egao@gmail.com | I4: 45992.761
B5: ahaba.300@gmail.com | C5: 45993.425 | E5: eririn2025@gmail.com | F5: 45994.118 | H5: pigmpooh@gmail.com | I5: 45995.466
B6: chibi91bisu1027@docomo.ne.jp | C6: 45993.721 | E6: reviewuser@yahoo.co.jp | F6: 45994.634 | H6: ahrm26912@gmail.com | I6: 45996.062
B7: tkf585855@gmail.com | C7: 45994.244 | E7: cocoweb50@gmail.com | F7: 45994.977 | H7: reviewuser@yahoo.co.jp | I7: 45996.518
B8: nre59754@gmail.com | C8: 45994.669 | E8: ahrm26912@gmail.com | F8: 45995.854 | H8: sonicbtob@gmail.com | I8: 45998.56
B9: rumi261303@gmail.com | C9: 45994.961 | E9: laneige1221@gmail.com | F9: 45999.809 | H9: kitakan09@gmail.com | I9: 46001.475
B10: cocoweb50@gmail.com | C10: 45994.975 | E10: kitakan09@gmail.com | F10: 46000.893 | H10: thomas_m.k.night@icloud.com | I10: 46001.717
B11: akihiro_1_takahashi@yahoo.co.jp | C11: 45995.227 | E11: isamu36323@gmail.com | F11: 46001.074 | H11: greenleaftwo7@gmail.com | I11: 46002.386
B12: ahrm26912@gmail.com | C12: 45995.82 | E12: subarattino@gmail.com | F12: 46001.322 | H12: info@contrail2022.com | I12: 46003.551
B13: gogatu026.01@gmail.com | C13: 45996.408 | E13: greenleaftwo7@gmail.com | F13: 46001.734 | H13: sakura.kougirou@icloud.com | I13: 46004.253
B14: hikaru414@gmail.com | C14: 45996.628 | E14: big.fishing.t.m@icloud.com | F14: 46002.754 | H14: subarattino@gmail.com | I14: 46004.403
... B32: joe.shibahara@iCloud.com | C32: 46006.026 | E32: udna224488@gmail.com | F32: 46009.912 | H32: laneige1221@gmail.com | I32: 46020.23
B33: rsg70208@gmail.com | C33: 46006.236 | E33: keichan.su.0716@gmail.com | F33: 46009.95
B34: yajimaen82000@gmail.com | C34: 46006.343 | E34: Torontolife.jp@gmail.com | F34: 46010.01
B35: hellochimi03@ymail.ne.jp | C35: 46006.359 | E35: kunitamagen0803@gmail.com | F35: 46010.368
B36: yorukiyo8@gmail.com | C36: 46006.491 | E36: miko171825@gmail.com | F36: 46010.669
B37: a7song7for7you@gmail.com | C37: 46006.509 | E37: keihiro7138@gmail.com | F37: 46011.449
B38: masato.world.7@gmail.com | C38: 46006.589 | E38: memekaibara721@gmail.com | F38: 46011.845
B39: k204149@yahoo.co.jp | C39: 46006.842 | E39: janne515@ozzio.jp | F39: 46012.584
B40: kanonpapa49@icloud.com | C40: 46007.449 | E40: satoshi.oj@gmail.com | F40: 46012.759
B41: w2022128124@gmail.com | C41: 46007.718 | E41: rmqwb771@gmail.com | F41: 46012.776
B42: amekuromk@gmail.com | C42: 46007.98 | E42: inainaemi@gmail.com | F42: 46013.05
B43: drmfs50@gmail.com | C43: 46008.294 | E43: follow_the_wind123@yahoo.co.jp | F43: 46013.273
B44: 3655hayashi884@gmail.com | C44: 46008.336 | E44: sunnys.tamada@gmail.com | F44: 46013.352
... B53: tt38mm@i.softbnk.jp | C53: 46010.627 | E53: y.tsumita@gmail.com | F53: 46019.8
B54: janne515@ozzio.jp | C54: 46010.963
B55: watanabe.naoki1111@i.softbank.jp | C55: 46011.803
B56: tintirorin3721@gmail.com | C56: 46012.228
B57: hirojp64@gmail.com | C57: 46012.462
B58: gennoji555@yahoo.co.jp | C58: 46012.558
B59: aincenote@gmail.com | C59: 46012.669
B60: 1st.sr400@gmail.com | C60: 46012.734
B61: follow_the_wind123@yahoo.co.jp | C61: 46012.886
B62: inainaemi@gmail.com | C62: 46012.995
B63: nakayamamitiohujio@gmail.com | C63: 46013.233
B64: ohtsuka@spre-ad.co.jp | C64: 46013.38
B65: kazu76698082@gmail.com | C65: 46013.497
... B84: rikiriki5188858@gmail.com | C84: 46022.92

Sheet 20261月
B2: メルマガ登録者(重複なし) | C2: 登録日時 | E2: 審査フォーム回答者(重複なし) | F2: 登録日時 | H2: 個別相談予約者(重複なし) | I2: 登録日時
B3: goodfeeling.goodtiming@gmail.com | C3: 46023.872 | E3: karua1229@yahoo.co.jp | F3: 46023.65 | H3: karua1229@yahoo.co.jp | I3: 46023.986
B4: seakaorulove@icloud.com | C4: 46024.907 | E4: rikiriki5188858@gmail.com | F4: 46023.897 | H4: youko405xx@gmail.com | I4: 46025.958
B5: hama_fuji888@icloud.com | C5: 46024.944 | E5: goodfeeling.goodtiming@gmail.com | F5: 46023.939 | H5: goodfeeling.goodtiming@gmail.com | I5: 46026.921
B6: hidejr1031@gmail.com | C6: 46024.948 | E6: wwkd2324@yahoo.co.jp | F6: 46025.173 | H6: ai_yasuda0806@icloud.com | I6: 46027.393
B7: dbxxhirokixxdb@yahoo.co.jp | C7: 46024.952 | E7: ai_yasuda0806@icloud.com | F7: 46025.707 | H7: unkotintindahhunda@icloud.com | I7: 46030.809
B8: taksfumi@gmail.com | C8: 46025.011 | E8: youko405xx@gmail.com | F8: 46025.863 | H8: keihiro7138@gmail.com | I8: 46032.594
B9: mirai2yume5050@gmail.com | C9: 46025.018 | E9: t16048857@gmail.com | F9: 46028.818 | H9: neoagile@gmail.com | I9: 46032.9
B10: noburinco1954@gmail.com | C10: 46025.078 | E10: unkotintindahhunda@icloud.com | F10: 46030.519 | H10: t16048857@gmail.com | I10: 46033.84
B11: michiaki0813@gmail.com | C11: 46025.1 | E11: eternalshallows@gmail.com | F11: 46032.402 | H11: cryptocurr1824@gmail.com | I11: 46035.077
B12: wwkd2324@yahoo.co.jp | C12: 46025.171 | E12: imay.103.fintx@gmail.com | F12: 46032.962 | H12: ronchi0527@gmail.com | I12: 46035.979
B13: marupappa@gmail.com | C13: 46025.243 | E13: uagq01ejh5edjw0p1kxe@docomo.ne.jp | F13: 46033.994 | H13: sundream715@yahoo.co.jp | I13: 46037.533
B14: beer.taka427@ezweb.ne.jp | C14: 46025.454 | E14: yatsutsuka@gmail.com | F14: 46034.632 | H14: takec3.1824@gmail.com | I14: 46038.849
B15: ai_yasuda0806@icloud.com | C15: 46025.668 | E15: ronchi0527@gmail.com | F15: 46035.851
B16: youko405xx@gmail.com | C16: 46025.833 | E16: sundream715@yahoo.co.jp | F16: 46036.365
B17: t16048857@gmail.com | C17: 46025.913 | E17: iesan.565622@gmail.com | F17: 46042.864
B18: yumeart369@gmail.com | C18: 46025.995
B19: n09046793594@docomo.ne.jp | C19: 46026.028
B20: mma71521@gmail.com | C20: 46026.387
B21: regalmente2008@gmail.com | C21: 46026.582
B22: noris216@yahoo.co.jp | C22: 46026.788
B23: buriburi43214321@gmail.com | C23: 46026.9
B24: hitomin104@kagi.be | C24: 46027.19
B25: djibril325@gmail.com | C25: 46027.321
B26: shigekof18255@yahoo.co.jp | C26: 46028.037
B27: imay.103.fintx@gmail.com | C27: 46028.512
B28: clover-wvw18870@ymobile.ne.jp | C28: 46028.58
B29: mickeyssatsuki@gmail.com | C29: 46028.681
... B85: sadamasa0119@gmail.com | C85: 46043.367

Sheet >input

Sheet メルマガ登録者
A1: 全シナリオ共通読者ID | B1: LINE友だちID | C1: アカウント共通LINE友だちID | D1: LINE登録名 | E1: 現在のメールアドレス | F1: 新しいメールアドレス | G1: 姓 | H1: 名 | I1: フリガナ | J1: 電話番号 | K1: 郵便番号 | L1: 都道府県 | M1: 市区町村 | N1: 番地 | O1: マンション名 部屋番号 | P1: イベント参加日 | Q1: 登録経路 | R1: 配信基準日時 | S1: 登録日時 | T1: 登録元ページ | U1: 登録元IP | V1: ステータス | W1: 解除日時
A2: CzcYUulM2Zfh | B2: fOgp49wHsqE3 | C2: 80aae274c808838ff103efb824f998ea | D2: noriko | R2: 45850.595 | S2: 45850.595 | V2: 購読中
A3: 0iQZuhwjutVu | B3: FnbVaYBg6jvh | C3: 5970373b205fbee54b7bf44b9fa6fafc | D3: nomura | R3: 45850.627 | S3: 45850.627 | V3: 購読中
A4: iCd22MGnlrXI | B4: TD4OblGmTsH6 | C4: 0d69f65fda673e09aa44d16daba64979 | D4: 藤田 ちなつ | R4: 45850.655 | S4: 45850.655 | V4: 購読中
A5: bOxbkHktQc6c | B5: 95wkYIgeb01u | C5: 6c6e980945313ec3c552e504601c1d13 | D5: 八津川ひとえ | R5: 45850.668 | S5: 45850.668 | V5: 購読中
A6: Pr807vBpKmyN | B6: Osj7rz79bsVe | C6: c80fe6531ee27d3d213337c3391d0f1c | D6: としちゃん | R6: 45850.718 | S6: 45850.718 | V6: 購読中
A7: TgU462j6OHqP | B7: ct4L283Bwb6h | C7: e9747267306322b465f5227e3b8cde0e | D7: K@Emori | R7: 45850.777 | S7: 45850.777 | V7: 購読中
A8: bi5BlC1VwExM | B8: P2XYdhRH216E | C8: 378a67c328c0c86a8c2cbe586554c5b2 | D8: 前川 | R8: 45850.827 | S8: 45850.827 | V8: 購読中
A9: PQ5iLiPE8cqN | B9: QGJJ0PKtkBr9 | C9: 40844f056850f7545e689f9484a4cefd | D9: 華 | R9: 45850.836 | S9: 45850.836 | V9: 購読中
A10: Enau0Jz0dvzn | B10: hJxtkcJGrn8v | C10: 92538f93cfc534b748fe26d8f671bfbe | D10: おぎけん | R10: 45850.845 | S10: 45850.845 | V10: 購読中
A11: R7qgvKa715Qy | B11: 8e1QswUwiL5o | C11: d5153f91eb9557820f053fbad50c3a35 | D11: 航央 | R11: 45850.85 | S11: 45850.85 | V11: 購読中
A12: hKNMu81dpfvn | B12: UiNEBvP67opx | C12: b008a6adaa3f17ebfe3313080ab43664 | D12: けら | R12: 45850.886 | S12: 45850.886 | V12: 購読中
A13: 9eWSXv7MNcFc | B13: hW8JGtn5oRTf | C13: 533502f7f8e7305167a797fca8a0c8ad | D13: Nori??Su | R13: 45850.891 | S13: 45850.891 | V13: 購読中
... A322: palYURKw1UYi | B322: brExFzg3W0Jk | C322: b5145a2976703a0c5e583b8b505416ee | D322: 岩井文好(LLC岩井工業) | R322: 45860.582 | S322: 45860.582 | V322: 購読中
A323: jg2nwYIJCAvi | B323: OckwDm0iX8V5 | C323: a9cc3d07f40855c2ba5865b6cb5f0866 | D323: 610 | R323: 45860.633 | S323: 45860.633 | V323: 購読中
A324: GkHGpO6QG7k8 | B324: iKZ3zCQTIo53 | C324: 64a9c7301fcbdf8c19619c74c8cbed4f | D324: Macha | R324: 45860.646 | S324: 45860.646 | V324: 購読中
A325: cOErZgm6uvJk | B325: HcgNavajifRT | C325: d3076467a505298c52ff48a05268a14b | D325: 剛志 | R325: 45860.723 | S325: 45860.723 | V325: 購読中
A326: BIZ8YNt2TiD9 | B326: XP6N8Pgu62et | C326: f6bf07533bb307ce3aae7da6959da2c5 | D326: 工藤 (藤岡 )久子 | R326: 45860.725 | S326: 45860.725 | V326: 購読中
A327: 1FU9oi4CavSr | B327: xyfwi6JMpdwD | C327: d314f3ba73759a6bd386e79db809feda | D327: 藤田 水産 | R327: 45860.746 | S327: 45860.746 | V327: 購読中
A328: g9CVWVCeYDqv | B328: lgPiBDHavLXu | C328: 3f65b37280977e74fb5af896ab83dfd6 | D328: akira nagahama | R328: 45860.792 | S328: 45860.792 | V328: 購読中
A329: fNBjDyrUcfK7 | B329: tNV9F5i0Of9n | C329: 693125590f6c279fe9c736d99db3fa8f | D329: 小櫻 辰秋 | R329: 45860.839 | S329: 45860.839 | V329: 購読中
A330: e3vZ0o2mrQ9a | B330: g9gYc7eAn4iM | C330: 9a6129d73b48c91050d780f4f9a015db | D330: 富樫学 | R330: 45860.89 | S330: 45860.89 | V330: 購読中
A331: lv17l2CfkYfB | B331: E9BTVETaTsPo | C331: d91b11de83958295d214832c8b805e86 | D331: suzuhigashi kota | R331: 45860.89 | S331: 45860.89 | V331: 購読中
A332: IT879s5HwsEE | B332: nh2xmjUs28Ky | C332: 497339e960c137ba6c54f124197502cb | D332: マッチ | R332: 45860.893 | S332: 45860.893 | V332: 購読中
A333: TvQQLPb0utJd | B333: bsZR9kVvoFOv | C333: 85a965967f1861ff6c739919ca9e8952 | D333: 松本直 | R333: 45860.896 | S333: 45860.896 | V333: 購読中
A334: YsD8NDElDfxi | B334: 2FmAtAe7RXrm | C334: f2356750b8ffb7e5da86f8f1059085a5 | D334: ぱにえ TORIKAGO | R334: 45860.905 | S334: 45860.905 | V334: 購読中
A335: UJ6rvdKOxheJ | B335: gCz5i55ha2N9 | C335: 2bd6de67291978d5a12c9f82465e10bc | D335: Nitta Keisuke | R335: 45860.91 | S335: 45860.91 | V335: 購読中
... A663: 7pyAhdAPw4ev | B663: V1o9wUy18pi5 | C663: b941820abbef9ffb85b10f1941bc2d8a | D663: Reina Tanaka | R663: 45876.932 | S663: 45876.932 | V663: 購読中
A664: k0jmAdN8UnTt | E664: 田中玲奈 | F664: rn010240@gmail.com | R664: 45876.933 | S664: 45876.933 | T664: https://sub.shirogakucho-web3.com/r/ohH4pKEyuKzr/register | U664: 221.248.180.22 | V664: 購読中
A665: hHyIemaa4N3k | B665: YRdfvCYuhyBF | C665: c0a25d2634b9e5e527fd29b79c31cf69 | D665: 神岡 阿修羅 | R665: 45877.025 | S665: 45877.025 | V665: 購読中
A666: 2E2uEmtCj85d | B666: mQk2C6lfwMSX | C666: 4290262199fadef62756dcd7e29c9a1a | D666: 佐藤亮二 | R666: 45877.204 | S666: 45877.204 | V666: 購読中
A667: UeOTOMndTaDB | B667: tVrW3iUNIPFj | C667: d1131a8db63c25f74a18694ce607a432 | D667: 杉川 Naoko | R667: 45877.324 | S667: 45877.324 | V667: 購読中
A668: RrmjpjFU0RsW | B668: NJXDQHV0rqiy | C668: 9ee050f1ea8d5b2be25ec7c005533690 | D668: momo? | R668: 45877.37 | S668: 45877.37 | V668: 購読中
A669: XfGwohOOfeSx | B669: FkQDKtl0TeOE | C669: d5a64957c7b4339a70fda0c889f3970a | D669: 孝広 | R669: 45877.392 | S669: 45877.392 | V669: 購読中
A670: XfGwohOOfeSx | B670: FkQDKtl0TeOE | C670: d5a64957c7b4339a70fda0c889f3970a | D670: 孝広 | R670: 45877.392 | S670: 45877.392 | V670: 購読中
A671: 5gZkrz4bZYPt | B671: AtL0rxv7YKB6 | C671: 57eb511242564abe28efe9283941a26c | D671: Y.I | R671: 45877.431 | S671: 45877.431 | V671: 購読中
A672: huAjRS8VkIMe | B672: OL6rQs3JZ7Es | C672: baafb13be0d44e762a9cf3d50b73a14c | D672: すがぬま こういち | R672: 45877.546 | S672: 45877.546 | V672: 購読中
A673: EcLlg86LMrO5 | B673: yOS7g0GPnhJE | C673: 85f5797ead026ea3a92ee5ed4930a924 | D673: 酒井 | R673: 45877.805 | S673: 45877.805 | V673: 購読中
A674: ogBJqzXNUnlr | E674: じん | F674: jin.hitoshi@gmail.com | R674: 45877.814 | S674: 45877.814 | T674: https://sub.shirogakucho-web3.com/r/ohH4pKEyuKzr/register | U674: 240b:c020:4d2:79f8:3c84:e717:6d98:4eb5 | V674: 購読中
A675: vvlJwuAKXSrh | E675: 松浦 | F675: akikoko0110@yahoo.co.jp | R675: 45877.814 | S675: 45877.814 | T675: https://sub.shirogakucho-web3.com/r/ohH4pKEyuKzr/register | U675: 2001:ce8:144:b55b:8d7a:e32b:e1d4:5d1a | V675: 購読中
...

Sheet 審査フォーム回答者①
A1: 全シナリオ共通読者ID | B1: LINE友だちID | C1: アカウント共通LINE友だちID | D1: LINE登録名 | E1: お名前 | F1: メールアドレス | G1: 姓 | H1: 名 | I1: フリガナ | J1: 電話番号 | K1: 郵便番号 | L1: 都道府県 | M1: 市区町村 | N1: 番地 | O1: マンション名 部屋番号 | P1: イベント参加日 | Q1: 現在の仮想通貨投資レベルを教えてください！ | R1: 現在の月収を教えてください！ | S1: 有料の「トレードスクール」に興味ありますか？ | T1: その他シロ学長へのメッセージ・聞きたいこと | U1: お名前 | V1: 面談で聞きたいこと・解決したいお悩みを教えてください！(選択式) | W1: 登録経路 | X1: 配信基準日時 | Y1: 登録日時 | Z1: 登録元ページ | AA1: 登録元IP | AB1: ステータス | AC1: 解除日時
A2: TllJMv4INfZr | E2: 吉田 隆 | F2: ty11055yoshi@gmail.com | Q2: 未経験 | R2: 50万くらい | S2: ある | T2: いつもYoutube楽しみいしてます。 | U2: 吉田隆 | X2: 45884.795 | Y2: 45884.795 | Z2: https://sub.shirogakucho-web3.com/p/jwf1rmhnKm4S | AA2: 240f:102:f60c:1:f86f:81f3:f7c8:ba9f | AB2: 解除済 | AC2: 45911.229
A3: OYgI3YxHf4x4 | E3: 増山 武彦 | F3: take.mas1969@gmail.com | Q3: 未経験 | R3: 50万円 | S3: ない | T3: 現在、天然ガスの投資に失敗して、損切した金額100万円を毎月返済しています。シロ学長が説明される内容を勉強したい。 | U3: 増山武彦 | X3: 45884.795 | Y3: 45884.795 | Z3: https://sub.shirogakucho-web3.com/p/jwf1rmhnKm4S | AA3: 2404:7a85:4860:2f00:b991:b57b:50d7:1b2 | AB3: 購読中
A4: XwUE3ZIRp5VH | E4: 藤原 克哉 | F4: fujiwara.katsuya@gmail.com | Q4: 経験あり | R4: 30万円程度 | S4: ある | T4: ｙ楽しみにしています！ | U4: 藤原克哉 | X4: 45884.796 | Y4: 45884.796 | Z4: https://sub.shirogakucho-web3.com/p/jwf1rmhnKm4S | AA4: 2404:7a84:3c60:e00:10ca:e8fd:80ef:4763 | AB4: 購読中
A5: Qnt4R4VPmu4R | E5: 宮本 義孝 | F5: mymtystk@gmail.com | Q5: 初心者 | R5: 50万程度 | S5: ある | T5: よろしくお願いします | U5: 宮本義孝 | X5: 45884.796 | Y5: 45884.796 | Z5: https://sub.shirogakucho-web3.com/p/jwf1rmhnKm4S | AA5: 58.70.182.228 | AB5: 購読中
A6: qYXDaYqfsb3E | E6: 櫛田 直 | F6: nao394d@gmail.com | Q6: 初心者 | R6: 50 | S6: ある | T6: 先ずは勉強したいです | U6: 櫛田直 | X6: 45884.796 | Y6: 45884.796 | Z6: https://sub.shirogakucho-web3.com/p/jwf1rmhnKm4S | AA6: 220.211.86.70 | AB6: 購読中
A7: HtYdsZVsKM2v | E7: 鎭目 真喜子 | F7: shizumemakiko@gmail.com | Q7: 初心者 | R7: 20万以下 | S7: ない | T7: シングルの母なので、自立してやっていける力をつけたいです。宜しくお願いします。 | U7: 鎭目 真喜子 | X7: 45884.798 | Y7: 45884.798 | Z7: https://sub.shirogakucho-web3.com/p/jwf1rmhnKm4S | AA7: 58.12.1.1 | AB7: 解除済 | AC7: 45889.756
A8: gTFnGp2CVJtw | E8: 水間 将誉 | F8: mmizuma@gmail.com | Q8: 初心者 | R8: 30万 | S8: ある | T8: 老後の資金を作りたい | U8: 水間将誉 | X8: 45884.8 | Y8: 45884.8 | Z8: https://sub.shirogakucho-web3.com/p/jwf1rmhnKm4S | AA8: 2400:4050:c164:1e00:1cdb:858a:30c:a787 | AB8: 購読中
A9: gwDgFYKmElzE | E9: 木村 和美 | F9: millenniumstar8@gmail.com | Q9: 初心者 | R9: 0 | S9: ない | T9: Youtube楽しく見ています。ハワイ在住です。私も昔300万円仮想通貨で消えました。住宅ローン早く返したいです。どうぞよろしくお願いします！ | U9: 木村和美 | X9: 45884.802 | Y9: 45884.802 | Z9: https://sub.shirogakucho-web3.com/p/jwf1rmhnKm4S | AA9: 2603:800c:12f0:2030:8d0e:a99c:a91b:37c7 | AB9: 購読中
A10: 5ZYHptx28VYZ | E10: 酒井 由美 | F10: yamayu0462@gmail.com | Q10: 中級位です | R10: 100前後 | S10: ある | T10: 仮想通貨の情報をワクワクしながらyou tubeで拝見しております。どうもありがとうございます。 | U10: 酒井由美 | X10: 45884.802 | Y10: 45884.802 | Z10: https://sub.shirogakucho-web3.com/p/jwf1rmhnKm4S | AA10: 114.48.188.145 | AB10: 解除済 | AC10: 45888.282
A11: Dh9hYNpEZJoJ | E11: 黄本 章雄 | F11: smile.jack317@docomo.ne.jp | Q11: 初心者 | R11: 使えるお金が、5万～頑張って10万いかるかなー | S11: ない | T11: 普段から、パソコン、スマホも使えない私ですが、宜しくお願いします??? | U11: キモトアキオ | X11: 45884.803 | Y11: 45884.803 | Z11: https://sub.shirogakucho-web3.com/p/jwf1rmhnKm4S | AA11: 240b:250:58e1:c00:cd0e:beb1:1479:32bd | AB11: 購読中
A12: d2TSp63d0Y1g | F12: s.takeda000@icloud.com | Q12: 初心者 | R12: 50万程度 | S12: ある | T12: これから仮想通貨を学びたいと思いますので宜しくお願い致します | U12: 武田 慎吾 | X12: 45884.805 | Y12: 45884.805 | Z12: https://sub.shirogakucho-web3.com/p/jwf1rmhnKm4S | AA12: 2400:4153:2064:c010:5494:256a:dc1c:fb8c | AB12: 購読中
A13: e8oksGRnuklE | E13: 門田 典美 | F13: ganbamonta@gmail.com | Q13: 初心者 | R13: 30万円以下 | S13: ない | T13: 何度もYouTubeを見返して勉強させていただいています。なかなかサクサク頭に入っていかないことの多いのですがしっかりついていきたいと思います。私も多くの詐欺に遭ったばかりでまとまった額の投資は難しいのですが、よろしくお願いします | U13: 門田 典美 | X13: 45884.805 | Y13: 45884.805 | Z13: https://sub.shirogakucho-web3.com/p/jwf1rmhnKm4S | AA13: 60.102.49.166 | AB13: 購読中
A14: Z6CbT7fbjgwh | E14: 藤原 和憲 | F14: heckel371@yahoo.co.jp | Q14: 初心者 | R14: 20万円 | S14: ある | U14: 藤原和憲 | X14: 45884.807 | Y14: 45884.807 | Z14: https://sub.shirogakucho-web3.com/p/jwf1rmhnKm4S | AA14: 2001:ce8:184:4442:18a0:4f43:82f1:ba19 | AB14: 購読中
A15: X0pIRMuMuiYa | F15: yoh.sekido@gmail.com | Q15: 中級者 | R15: 50万 | S15: ある | T15: 宜しくお願いします。 | U15: 関戸 | X15: 45884.818 | Y15: 45884.818 | Z15: https://sub.shirogakucho-web3.com/p/jwf1rmhnKm4S | AA15: 2405:6581:51e0:7b00:bc11:68cb:b633:8e9e | AB15: 購読中
A16: qVjoToPccxkm | E16: 丸山 満男 | F16: dady152@gmail.com | Q16: 初心者 | R16: 20万以下 | S16: ある | T16: 宜しくお願い致します | U16: 丸山満男 | X16: 45884.822 | Y16: 45884.822 | Z16: https://sub.shirogakucho-web3.com/p/jwf1rmhnKm4S | AA16: 180.92.25.132 | AB16: 購読中
A17: qYXDaYqfsb3E | E17: 櫛田 直 | F17: nao394d@gmail.com | Q17: 初心者 | R17: 50万円程度 | S17: ある | T17: 私も詐欺に遭い、やり直したいと考えています。専門家の力を借りて頑張りたいと考えています。よろしくお願いします。 | U17: 櫛田直 | X17: 45884.824 | Y17: 45884.824 | Z17: https://sub.shirogakucho-web3.com/p/jwf1rmhnKm4S | AA17: 220.211.86.70 | AB17: 購読中
A18: Y4I87GbIs9QD | E18: 滝本 晴子 | F18: supuring0709@gmail.com | Q18: 初心者 | R18: 22万 | S18: ある | U18: 滝本 晴子 | X18: 45884.824 | Y18: 45884.824 | Z18: https://sub.shirogakucho-web3.com/p/jwf1rmhnKm4S | AA18: 211.15.20.244 | AB18: 解除済 | AC18: 45890.327
A19: maBjLxvUHlnP | E19: 登田 英樹 | F19: towahide091q@gmail.com | Q19: 中級 | R19: 50万 | S19: ある | T19: 仮想通貨には5年位関わっていますが、数々の詐欺に遭ってきました。今はトレードはなく現物のコインを毎月少しずつ買っていますが、手持ちの資金が減ってきています。本業も忙しいのですが、少しずつ勉強しながら学んでいきたいです。よろしくお願いします。 | U19: 登田英樹 | X19: 45884.825 | Y19: 45884.825 | Z19: https://sub.shirogakucho-web3.com/p/jwf1rmhnKm4S | AA19: 153.201.87.32 | AB19: 購読中
A20: fcWKgGmD9sB8 | E20: 原野 智哉 | F20: tom1966_11@hotmail.com | Q20: 仮想通貨投資を始めて6ヶ月ですが、知識がまだ浅いです。 | R20: 月収は50万円程度です。 | S20: ある | T20: 現在、娘が2名おり、長女が高1、次女が6年生です。大学への学費などを準備したいと思っています。また自分は60歳手前であり、そのためにこの5年で1000万円、10年で3000万円程度は資金を作りたいと思っています。退職金は安定した退職後の生活に回す必要があるのです。トレードは初めてですが、シロ学長の方法を学ばせてください。他のYouTubeのトレード戦略はよくわかりませんでした。 | U20: 原野 智哉 | X20: 45884.826 | Y20: 45884.826 | Z20: https://sub.shirogakucho-web3.com/p/jwf1rmhnKm4S | AA20: 202.28.7.62 | AB20: 購読中
A21: t395JN2sySTE | E21: 藤堂 憲子 | F21: britelightone1@gmail.com | Q21: やるしかない！初心者です！ | R21: 0円 | S21: ある | T21: 3人同時介護中で預金を切り崩し、体調も崩し、これではいけないとシロさんに辿り着きました。20年前に中央アフリカ大使に1200万円の詐欺にあい、働きながら医療系夜間学校に通っていた為、学費を「いけない事」して稼ぐしかありませんでした。3人同時介護の前も人の面倒ばかりでいい加減に自分の生活を取り戻したい、暗号通貨の世界は面白い！が繋がり、シロ学長のYoutubeを見ていて震えました。中長期のプロジェクトへの投資はしましたが、それまでどうするの？私はもう53歳だよ？10年後って。。。そこまで何とか利益を確保出来る手段がないかな、とずーーーっと考えていました。機械音痴でやっと最近キャッシュレスでのお買い物が出来るようになりました。プレミアロジックの動画は何となくしか理解が出来ませんでしたが今の私の生活でも利益が出せる！深呼吸が出来る！両親と伯母をヘルパーさんに託して(支払って)外へ行けるようになる！その為なら移動中でも勉強をしたい！！成果を出したい！そういう気持ちです。学ぶにはお金がかかるのが普通ですが、それさえもキツい生活です。でもシロ学長のロジックをしっかりと学べるならお返しをしたい！です。PDFだけで見ると頭痛がしてきますがシロ学長なら私のような初心者の為の対応を絶対にして下さる！かなり神頼み的になってしまいましたが、本当に初心者の私でもついて行きますのでどうぞ宜しくお願い致します！ | U21: 藤堂憲子 | X21: 45884.827 | Y21: 45884.827 | Z21: https://sub.shirogakucho-web3.com/p/jwf1rmhnKm4S | AA21: 2400:4050:8801:9c00:3d89:787e:1a57:c3b7 | AB21: 購読中
A22: RuqbIbOkDaq1 | E22: 鵜野 彰洋 | F22: au09054720010@gmail.com | Q22: 初心者 | R22: 90万 | S22: ある | T22: 楽しみにしています。稼ぐ力、着けたいです！ | U22: 鵜野彰洋 | X22: 45884.828 | Y22: 45884.828 | Z22: https://sub.shirogakucho-web3.com/p/jwf1rmhnKm4S | AA22: 240b:252:e60:2800:d4f9:4b18:5f3c:5802 | AB22: 購読中
A23: g557hMPanUIH | F23: jamiko0705@yahoo.co.jp | Q23: 初心者 | R23: 10万円 | S23: ない | T23: 分かりやすいYouTubeをどうもありがとうございます！ | U23: 川津明日香 | X23: 45884.828 | Y23: 45884.828 | Z23: https://sub.shirogakucho-web3.com/p/jwf1rmhnKm4S | AA23: 2001:268:987f:753d:315c:9b56:2619:41af | AB23: 購読中
A24: 3DEdw698qXc9 | E24: 中山 和人 | F24: mikura1969@icloud.com | Q24: 初心者 | R24: 50万 | S24: ある | T24: 57歳のサラリーマンで副業で物販をしていますが、物販の副業で儲け続ける難しさを痛感しています。効率良く安定した収益を仮想通貨であげれるようにぜひともなりたいのでよろしくお願い致します。 | U24: 中山和人 | X24: 45884.83 | Y24: 45884.83 | Z24: https://sub.shirogakucho-web3.com/p/jwf1rmhnKm4S | AA24: 2001:268:73b6:d61c:fd7f:dff6:5560:370a | AB24: 購読中
A25: hOWycn41njc4 | E25: 原口 優子 | F25: y6649851@gmail.com | Q25: 初心者 | R25: 20万円 | S25: ない | T25: よろしくお願いいたします。 | U25: 原口優子 | X25: 45884.831 | Y25: 45884.831 | Z25: https://sub.shirogakucho-web3.com/p/jwf1rmhnKm4S | AA25: 210.136.107.235 | AB25: 購読中
A26: Ioj0uHHtIjDy | E26: 轟 洋子 | F26: paribmw369@gmail.com | Q26: 未経験 | R26: 20万円以下 | S26: ある | T26: 有料で高いと参加できません。何ヶ月も勉強も出来ません。やる気はあります。 | U26: 轟 洋子 | X26: 45884.832 | Y26: 45884.832 | Z26: https://sub.shirogakucho-web3.com/p/jwf1rmhnKm4S | AA26: 2400:4051:c841:100:c855:8884:3f3a:74ac | AB26: 解除済 | AC26: 45958.657
A27: 5v4cfPq1B1Ci | F27: ktkhs@gmail.com | Q27: 未経験 | R27: 30万円程度 | S27: ある | T27: 色々勉強させてください。 | U27: 高橋 敬 | X27: 45884.833 | Y27: 45884.833 | Z27: https://sub.shirogakucho-web3.com/p/jwf1rmhnKm4S | AA27: 160.13.182.22 | AB27: 購読中/配信エラー
A28: Y4I87GbIs9QD | B28: fBA0pxPCPonl | C28: 3d91444815d3d53a5bf376f537ef3a89 | D28: 滝本 晴子 | E28: 滝本 晴子 | F28: supuring0709@gmail.com | Q28: 初心者 | R28: 22万 | S28: ある | T28: 副業しても上手く行かず老後の不安もあります。自由な時間も欲しい節約しないで生活したい今の生活変えたいです。宜しくお願いします。 | U28: 滝本晴子 | X28: 45884.833 | Y28: 45884.833 | Z28: https://sub.shirogakucho-web3.com/p/jwf1rmhnKm4S | AA28: 211.15.20.244 | AB28: 解除済 | AC28: 45890.327
A29: hQ4TwjsverNH | E29: 鈴木 宏一 | F29: h-suzuki@daiwack.co.jp | Q29: 初心者です | R29: 50万円程度 | S29: ある | T29: 会社員のため本業もありますので、ルールがあり淡々とトレードできるのは大変有り難いです。よろしくお願いいたします。 | U29: 鈴木宏一 | X29: 45884.835 | Y29: 45884.835 | Z29: https://sub.shirogakucho-web3.com/p/jwf1rmhnKm4S | AA29: 183.77.56.18 | AB29: 解除済 | AC29: 45907.63
A30: Y8n9eeYqJews | E30: 福島 修 | F30: w.rainey-0840@kuf.biglobe.ne.jp | Q30: 初心者 | R30: 30万円 | S30: ない | T30: プレミアムロジックがどのような手法か、興味があります。個別説明会に申し込みしたいと思います。 | U30: 福島 修 | X30: 45884.836 | Y30: 45884.836 | Z30: https://sub.shirogakucho-web3.com/p/jwf1rmhnKm4S | AA30: 2001:268:c215:58a:c1cd:8e67:19b1:4821 | AB30: 購読中
A31: 2enDrQfa7Fb9 | E31: 坂本 はるみ | F31: kotobukiwithin@gmail.com | Q31: 初心者 | R31: 35万円 | S31: ある | T31: いつも有益な発信感謝しています。にも関わらず、正直に申し上げると、教えに従って行動したにも関わらず、思ったような成果も出せないどころか、大損をしてしまったことも一度や二度ではありません。これまで大きな詐欺に五度遭い、損失総額は5千万円を超えます。株式やゴールドには一度も手を出したことはありませんが、FXをかなりランダムに取引して手数料で資産を溶かしてきました。2016～17年に人生初めて最大の詐欺に遭ってドン底を経験した時、起死回生を狙ってビットコインに手を出しましたが、きちんと勉強もせず周りが騒いでいるからという理由で買ったので、直ぐ不安になり全部売って手数料で損をし、その後そちらの世界には一切目をつぶって生きてきました。仮想通貨を改めて見直したのは、ほんの数ヶ月前からです。昨年から2回続けて投資詐欺に遭い叩きのめされても、AIを使った投資の可能性を捨てることができず、少しずつ我流で取引を始め、そんな中で仮想通貨に辿り着きました。6月末にシロ学長の教えに従って、BYBITでコピートレードから始めましたが中々思うように行かず、MEXCに土俵を移して先物トレードを始めました。レバレッジをたっぷり使って、危険な投資で少し儲けて気を大きくし大損するということを繰り返し、負けを取り戻そうと焦って益々危険な投資行動がエスカレート、変な画面に遭遇し、騙される酷い目に遭いました。それ以来、たった一週間程度の仮想通貨投資経験でしたが、怖くなり、一ヶ月近く、見るのも考えるのも嫌だという最低の精神状態を経験した末、ほんの数週間前からやっと、復活を期してページを開いてみることができるようになったものの、まだ怖くて取引に手を出せずにいます。怖くて見るのも嫌だった時には、もう大嫌いと思いましたが、今はやはり自信を持って取り組むことさえできれば好きなんだなぁとひしひし感じ、自信を持って取り組むことができることへの憧れを強く感じています。是非シロ学長の様に自信を持って取引をし、自信を持ってそれを語れるようになりたい！今心からそう思って、熱意を持って学び続けることを心に誓って、個別説明会に申し込みさせていただきたいと思います。よろしくお願いします。巷には、既に億万長者なのにも関わらず、そうでない人を助けたいと言いながら、結局はお金儲けの道具としか見ていないような人が溢れています。シロ学長のように、有料級を無料で惜しみなく提供し続ける高貴なお方は稀有です。心から尊敬します。 | U31: 坂本はるみ | X31: 45884.845 | Y31: 45884.845 | Z31: https://sub.shirogakucho-web3.com/p/jwf1rmhnKm4S | AA31: 115.69.5.199 | AB31: 解除済 | AC31: 45969.494
A32: ha9DXTnxKJRS | B32: JYrVb5FakncW | C32: 9356dff92a589a573dfd24fec382d1af | D32: 仮想通貨大好き | E32: 大沼 駿介 | F32: greenteas77777@gmail.com | S32: ある | T32: 毎日非常に応援しています | U32: 大沼駿介 | X32: 45884.845 | Y32: 45884.845 | Z32: https://sub.shirogakucho-web3.com/p/jwf1rmhnKm4S | AA32: 103.5.140.180 | AB32: 解除済 | AC32: 45893.886
A33: jHr90M7oVglK | B33: YQfl3RAQuSBF | C33: 239d5cbce2aab8a938084c4668bbe623 | D33: Hiroyuki Chikaraishi | E33: 力石 弘行 | F33: Izaiyak@gmail.com | Q33: From 2020からの初心者です。 | R33: 1000000円 | S33: ある | T33: 色々と勉強をしてみたく、参加希望します。 | U33: HiroC | X33: 45884.846 | Y33: 45884.846 | Z33: https://sub.shirogakucho-web3.com/p/jwf1rmhnKm4S | AA33: 125.26.174.91 | AB33: 購読中
A34: jtcrxqbgxXIZ | E34: 松井 幸弘 | F34: den35738@protonmail.com | Q34: 初心者 投資経験６ヵ月 | R34: 25万くらい | S34: ある | T34: 仮想通貨投資の本質って何でしょう？とても気になってしまいました。 | U34: 松井幸弘 | X34: 45884.85 | Y34: 45884.85 | Z34: https://sub.shirogakucho-web3.com/p/jwf1rmhnKm4S | AA34: 2404:7a84:84c1:100:e1fc:631a:bc04:4d88 | AB34: 購読中
A35: lkiTsoOTe43s | E35: 大江 昌夫 | F35: oe.masao@gmail.com | Q35: シロ学長のYouTubeを見て始めたばかりの初心者です | R35: 45万円程度 | S35: ない | T35: いつもわかりやすい動画ありがとうございます。私は親が残した負の財産がありその返済のため社畜のように働いてきましが、50を目の前にし自分の資産もなければ借金をただ返していくだけの人生は嫌だなと思い、残りの人生を幸せに過ごしたい！と思いこの春からニーサを始めました。いつまで健康でいられるかわからないし、元気なうちに余裕のある生活をしたいと思い、初めて観たYouTubeでシロ学長の動画に出会いました。私もシロ学長のように人生を豊かに生きてみたいと思い、申し込みさせて頂きました。どうぞよろしくお願いいたします。 | U35: 大江昌夫 | X35: 45884.852 | Y35: 45884.852 | Z35: https://sub.shirogakucho-web3.com/p/jwf1rmhnKm4S | AA35: 126.125.21.38 | AB35: 購読中
A36: O8HT8W9oYAer | E36: ホシコ カズヒサ | F36: kazu515257@ymail.ne.jp | Q36: 初心者 | R36: 20万 | S36: ある | T36: 自営業で年金もあてにならず、どうしたものかと、何かを始めなければ不安ですので出来る出来ないはさておき申し込みしました。 | U36: 星子和久 | X36: 45884.853 | Y36: 45884.853 | Z36: https://sub.shirogakucho-web3.com/p/jwf1rmhnKm4S | AA36: 240b:c010:610:20db:6c25:48f9:5fc3:ffe2 | AB36: 購読中
A37: e5bzaimJ0oCm | E37: 小高 和博 | F37: odaka_kazuhiro@yahoo.co.jp | Q37: 初心者 | S37: ある | T37: 他人の判断に頼るのでなく、また感情に振り回されることなく、一定のルールに基づき、淡々と売り買いできるようなりたいです。 | U37: 小高和博 | X37: 45884.869 | Y37: 45884.869 | Z37: https://sub.shirogakucho-web3.com/p/jwf1rmhnKm4S | AA37: 240b:c010:4d2:7ace:d5dc:c626:efdc:349e | AB37: 解除済 | AC37: 45904.611
A38: K6gh2TnaMGjA | E38: 山路 基洋 | F38: kmd249yamaji@gmail.com | Q38: 初心者 | R38: 20万円以下 | S38: ない | T38: 動画はなるほどと思える内容でした。取引所を選ぶ必要があることには、目から鱗です今まで考えたこともありませんでした。 | U38: 山路基洋 | X38: 45884.872 | Y38: 45884.872 | Z38: https://sub.shirogakucho-web3.com/p/jwf1rmhnKm4S | AA38: 133.149.93.80 | AB38: 購読中
A39: kZVFSY6jTtn7 | F39: taishomachi.tamai.y@gmail.com | Q39: 初心者 | R39: 20万以下 | S39: ある | T39: いつも動画ありがとうございます。数ある | U39: 玉井雄也 | X39: 45884.876 | Y39: 45884.876 | Z39: https://sub.shirogakucho-web3.com/p/jwf1rmhnKm4S | AA39: 123.219.23.204 | AB39: 購読中
A40: RaT6PpTaGPLl | F40: skyworudwairudo@gmail.com | Q40: 未経験 | R40: 26万円 | S40: ない | T40: はじめまして、自分は仮想通貨投資については全くの無知ですが、別な投資活動としてはバイナリーをやっていますが。安定とはほぼ遠く、何か未来があり、安定を得られる投資は無いかと考え、ユーチューブでたまたまシロ学長の動画を見つけ拝見させて頂き投資をもう一度しんけ | U40: obata | X40: 45884.885 | Y40: 45884.885 | Z40: https://sub.shirogakucho-web3.com/p/jwf1rmhnKm4S | AA40: 240b:c010:622:3dbe:35f1:424b:3e0c:e7ce | AB40: 購読中
...

Sheet 審査フォーム回答者②
A1: 全シナリオ共通読者ID | B1: LINE友だちID | C1: アカウント共通LINE友だちID | D1: LINE登録名 | E1: お名前 | F1: メールアドレス | G1: 姓 | H1: 名 | I1: フリガナ | J1: 電話番号 | K1: 郵便番号 | L1: 都道府県 | M1: 市区町村 | N1: 番地 | O1: マンション名 部屋番号 | P1: イベント参加日 | Q1: 登録経路 | R1: 配信基準日時 | S1: 登録日時 | T1: 登録元ページ | U1: 登録元IP | V1: ステータス | W1: 解除日時
A2: OYgI3YxHf4x4 | B2: iE7YkVVxHURT | C2: 711cb87b164b6b4ff959b801da956d3b | D2: Ta.m | E2: 増山 武彦 | F2: take.mas1969@gmail.com | R2: 45884.796 | S2: 45884.796 | V2: 購読中
A3: Qnt4R4VPmu4R | B3: NCh9l86UT2pX | C3: fed83fcf6177274178d9aae0ce1af3fb | D3: 宮本 義孝 | E3: 宮本 義孝 | F3: mymtystk@gmail.com | R3: 45884.796 | S3: 45884.796 | V3: 購読中
A4: qYXDaYqfsb3E | B4: AWFj3RtXK8Af | C4: 7ff0db4da65101568b655003744f1efa | D4: Kushida | E4: 櫛田 直 | F4: nao394d@gmail.com | R4: 45884.796 | S4: 45884.796 | V4: 購読中
A5: TllJMv4INfZr | B5: znieTIWhoyIe | C5: 4745124a6fab280d500d5b5bc0436c18 | D5: soulword | E5: 吉田 隆 | F5: ty11055yoshi@gmail.com | R5: 45884.797 | S5: 45884.797 | V5: 解除済 | W5: 45911.229
A6: XwUE3ZIRp5VH | B6: 0CiiwIqvDegW | C6: 0e7959b74f2c1e8bdeb99423750b6e80 | D6: かつや | E6: 藤原 克哉 | F6: fujiwara.katsuya@gmail.com | R6: 45884.797 | S6: 45884.797 | V6: 購読中
A7: gTFnGp2CVJtw | B7: EBymfg1BrZES | C7: ec755f96bd6c26454464151c60c79b2d | D7: mizupapa | E7: 水間 将誉 | F7: mmizuma@gmail.com | R7: 45884.8 | S7: 45884.8 | V7: 購読中
A8: gwDgFYKmElzE | B8: yDIk3BoZeqR3 | C8: f32681baef82e68704334dce9cfdc16a | D8: Kazumi | E8: 木村 和美 | F8: millenniumstar8@gmail.com | R8: 45884.802 | S8: 45884.802 | V8: 購読中
A9: 5ZYHptx28VYZ | B9: HIt9BGTn8QAx | C9: 032bf3422ee6913e9518fc1892774c9c | D9: さかい ゆみ | E9: 酒井 由美 | F9: yamayu0462@gmail.com | R9: 45884.803 | S9: 45884.803 | V9: 解除済 | W9: 45888.282
A10: Dh9hYNpEZJoJ | B10: 5dxHy3wf8JuC | C10: 173b50897c439f8eca6169371586a546 | D10: おさるさん | E10: 黄本 章雄 | F10: smile.jack317@docomo.ne.jp | R10: 45884.803 | S10: 45884.803 | V10: 購読中
A11: d2TSp63d0Y1g | B11: hEnTAzMQHnWV | C11: 87145cde3da7c71653c1ae5fdf6f6c0a | D11: 武田慎吾 | F11: s.takeda000@icloud.com | R11: 45884.805 | S11: 45884.805 | V11: 購読中
A12: Z6CbT7fbjgwh | B12: wPseBRsfNRze | C12: 34cf842afa10a7fb5d9a87df6e865e17 | D12: 藤原和憲 | E12: 藤原 和憲 | F12: heckel371@yahoo.co.jp | R12: 45884.807 | S12: 45884.807 | V12: 購読中
A13: X0pIRMuMuiYa | B13: mibpTNVHyME2 | C13: 299e5c1accf9f1c7213697d13baa408f | D13: 関戸 陽 | F13: yoh.sekido@gmail.com | R13: 45884.818 | S13: 45884.818 | V13: 購読中
A14: qVjoToPccxkm | B14: tiGbCCIe38YS | C14: 39de4a5d2abe7a60676496959d9a8600 | D14: maru | E14: 丸山 満男 | F14: dady152@gmail.com | R14: 45884.822 | S14: 45884.822 | V14: 購読中
A15: Y4I87GbIs9QD | B15: fBA0pxPCPonl | C15: 3d91444815d3d53a5bf376f537ef3a89 | D15: 滝本 晴子 | E15: 滝本 晴子 | F15: supuring0709@gmail.com | R15: 45884.825 | S15: 45884.825 | V15: 解除済 | W15: 45890.327
A16: maBjLxvUHlnP | B16: dcbF8Y6rnmxV | C16: 8ecea127199fdda7860f8950bcdf8796 | D16: 登田英樹 | E16: 登田 英樹 | F16: towahide091q@gmail.com | R16: 45884.826 | S16: 45884.826 | V16: 購読中
A17: fcWKgGmD9sB8 | B17: WzWF52TxUV65 | C17: 99a656201e9cc95a28d0d8672543a226 | D17: Tomoki Harano(原野智哉) | E17: 原野 智哉 | F17: tom1966_11@hotmail.com | R17: 45884.826 | S17: 45884.826 | V17: 購読中
A18: t395JN2sySTE | B18: y0Yn1zr0AwuA | C18: 2d6a72a101c76352dd457f12cd479b63 | D18: noriko okuzumi | E18: 藤堂 憲子 | F18: britelightone1@gmail.com | R18: 45884.827 | S18: 45884.827 | V18: 購読中
A19: RuqbIbOkDaq1 | B19: CqWKnrgnrO99 | C19: eaf287255ce8f1f6d5e91e9ef74cbc11 | D19: Akihiro Uno | E19: 鵜野 彰洋 | F19: au09054720010@gmail.com | R19: 45884.828 | S19: 45884.828 | V19: 購読中
A20: g557hMPanUIH | B20: 2vrE9VfGGjKH | C20: 0088a7b12641ce538886bd3bb7f350ab | D20: 川津明日香 | F20: jamiko0705@yahoo.co.jp | R20: 45884.828 | S20: 45884.828 | V20: 購読中
A21: 3DEdw698qXc9 | B21: nQxlzA5y83CX | C21: 1089d5db2375c78edea1c971c9bde99c | D21: NAKAYAMA 2175 | E21: 中山 和人 | F21: mikura1969@icloud.com | R21: 45884.83 | S21: 45884.83 | V21: 購読中
A22: hOWycn41njc4 | B22: q2qrBVEKGSRW | C22: 93abf46bf00b2235d5fa590e1a7789e8 | D22: ゆうこ | E22: 原口 優子 | F22: y6649851@gmail.com | R22: 45884.831 | S22: 45884.831 | V22: 購読中
A23: Ioj0uHHtIjDy | B23: nkL1y5lDBiFj | C23: 5391ff918f92392e796db71f06e93ba6 | D23: Doreml773 | E23: 轟 洋子 | F23: paribmw369@gmail.com | R23: 45884.832 | S23: 45884.832 | V23: 解除済 | W23: 45958.657
A24: 5v4cfPq1B1Ci | B24: ZSimEw0sC5VP | C24: 27a13c19884520b33b8c6932505a0a23 | D24: 高橋 敬 | F24: ktkhs@gmail.com | R24: 45884.833 | S24: 45884.833 | V24: 購読中/配信エラー
A25: hQ4TwjsverNH | B25: 94ZJ16u0hl5l | C25: 8b073b858e01f381032a7352e0d588f6 | D25: ＨＩＲＯ | E25: 鈴木 宏一 | F25: h-suzuki@daiwack.co.jp | R25: 45884.835 | S25: 45884.835 | V25: 解除済 | W25: 45907.63
A26: Y8n9eeYqJews | B26: ZjnBM60dhCCZ | C26: f76bb4fdaf454d8f08cc323eca0df0e7 | D26: fukufukuhappy | E26: 福島 修 | F26: w.rainey-0840@kuf.biglobe.ne.jp | R26: 45884.837 | S26: 45884.837 | V26: 購読中
